<?xml version="1.0" ?>
<!-- =================================================================================== -->
<!-- |    This document was autogenerated by xacro from /home/jelly/ros2_ws/src/mycobot-ros2-fix/mycobot_280_description/urdf/mycobot_280.urdf.xacro | -->
<!-- |    EDITING THIS FILE BY HAND IS NOT RECOMMENDED                                 | -->
<!-- =================================================================================== -->
<robot name="mycobot_280">
  <!--
    NOTE this is NOT a URDF. It cannot directly be loaded by consumers
    expecting a flattened '.urdf' file. See the top-level '.xacro' for that
    (but note that .xacro must still be processed by the xacro command).
  -->
  <!-- Create link fixed to the "world" -->
  <link name="world"/>
  <ros2_control name="mycobot_280" type="system">
    <hardware>
      <plugin>mycobot_hardware_interface/MyCobotHardwareInterface</plugin>
    </hardware>
    <joint name="joint1">
      <command_interface name="position">
        <param name="min">&quot;-3.139847324337799&quot;</param>
        <param name="max">3.139847324337799</param>
      </command_interface>
      <state_interface name="position">
        <!-- Initial position for the GenericSystem and simulation -->
        <param name="initial_value">0.0</param>
      </state_interface>
      <!-- <state_interface name="velocity"/> -->
    </joint>
    <joint name="joint2">
      <command_interface name="position">
        <param name="min">-3.139847324337799</param>
        <param name="max">3.139847324337799</param>
      </command_interface>
      <state_interface name="position">
        <!-- Initial position for the GenericSystem and simulation -->
        <param name="initial_value">0.0</param>
      </state_interface>
      <!-- <state_interface name="velocity"/> -->
    </joint>
    <joint name="joint3">
      <command_interface name="position">
        <param name="min">-3.139847324337799</param>
        <param name="max">3.139847324337799</param>
      </command_interface>
      <state_interface name="position">
        <!-- Initial position for the GenericSystem and simulation -->
        <param name="initial_value">0.0</param>
      </state_interface>
      <!-- <state_interface name="velocity"/> -->
    </joint>
    <joint name="joint4">
      <command_interface name="position">
        <param name="min">-3.139847324337799</param>
        <param name="max">3.139847324337799</param>
      </command_interface>
      <state_interface name="position">
        <!-- Initial position for the GenericSystem and simulation -->
        <param name="initial_value">0.0</param>
      </state_interface>
      <!-- <state_interface name="velocity"/> -->
    </joint>
    <joint name="joint5">
      <command_interface name="position">
        <param name="min">-3.139847324337799</param>
        <param name="max">3.139847324337799</param>
      </command_interface>
      <state_interface name="position">
        <!-- Initial position for the GenericSystem and simulation -->
        <param name="initial_value">0.0</param>
      </state_interface>
      <!-- <state_interface name="velocity"/> -->
    </joint>
    <joint name="joint6">
      <command_interface name="position">
        <param name="min">-3.139847324337799</param>
        <param name="max">3.139847324337799</param>
      </command_interface>
      <state_interface name="position">
        <!-- Initial position for the GenericSystem and simulation -->
        <param name="initial_value">0.0</param>
      </state_interface>
      <!-- <state_interface name="velocity"/> -->
    </joint>
  </ros2_control>
  <!-- links -  main serial chain -->
  <link name="base_link">
    <visual>
      <origin rpy="0 0 -1.5708" xyz="0 0 0"/>
      <geometry>
        <mesh filename="file:///home/jelly/ros2_ws/install/mycobot_280_description/share/mycobot_280_description/meshes/mycobot_280/base.stl"/>
      </geometry>
    </visual>
    <collision>
      <origin rpy="0 0 -1.5708" xyz="0 0 0"/>
      <geometry>
        <mesh filename="file:///home/jelly/ros2_ws/install/mycobot_280_description/share/mycobot_280_description/meshes/mycobot_280/base.stl"/>
      </geometry>
    </collision>
  </link>
  <link name="link1">
    <visual>
      <origin rpy="0 0 -1.5708" xyz="0 0 -0.06096"/>
      <geometry>
        <mesh filename="file:///home/jelly/ros2_ws/install/mycobot_280_description/share/mycobot_280_description/meshes/mycobot_280/link1.stl"/>
      </geometry>
    </visual>
    <collision>
      <origin rpy="0 0 -1.5708" xyz="0 0 -0.06096"/>
      <geometry>
        <mesh filename="file:///home/jelly/ros2_ws/install/mycobot_280_description/share/mycobot_280_description/meshes/mycobot_280/link1.stl"/>
      </geometry>
    </collision>
  </link>
  <link name="link2">
    <visual>
      <origin rpy="0 -1.5708 0" xyz="0 0 0.03256"/>
      <geometry>
        <mesh filename="file:///home/jelly/ros2_ws/install/mycobot_280_description/share/mycobot_280_description/meshes/mycobot_280/link2.stl"/>
      </geometry>
    </visual>
    <collision>
      <origin rpy="0 -1.5708 0" xyz="0 0 0.03256"/>
      <geometry>
        <mesh filename="file:///home/jelly/ros2_ws/install/mycobot_280_description/share/mycobot_280_description/meshes/mycobot_280/link2.stl"/>
      </geometry>
    </collision>
  </link>
  <link name="link3">
    <visual>
      <origin rpy="0 -1.5708 0" xyz="0 0 0.03056"/>
      <geometry>
        <mesh filename="file:///home/jelly/ros2_ws/install/mycobot_280_description/share/mycobot_280_description/meshes/mycobot_280/link3.stl"/>
      </geometry>
    </visual>
    <collision>
      <origin rpy="0 -1.5708 0" xyz="0 0 0.03056"/>
      <geometry>
        <mesh filename="file:///home/jelly/ros2_ws/install/mycobot_280_description/share/mycobot_280_description/meshes/mycobot_280/link3.stl"/>
      </geometry>
    </collision>
  </link>
  <link name="link4">
    <visual>
      <origin rpy="-1.5708 0 0" xyz="0 0 -0.03356"/>
      <geometry>
        <mesh filename="file:///home/jelly/ros2_ws/install/mycobot_280_description/share/mycobot_280_description/meshes/mycobot_280/link4.stl"/>
      </geometry>
    </visual>
    <collision>
      <origin rpy="-1.5708 0 0" xyz="0 0 -0.03356"/>
      <geometry>
        <mesh filename="file:///home/jelly/ros2_ws/install/mycobot_280_description/share/mycobot_280_description/meshes/mycobot_280/link4.stl"/>
      </geometry>
    </collision>
  </link>
  <link name="link5">
    <visual>
      <origin rpy="0 0 0" xyz="0 0 -0.038"/>
      <geometry>
        <mesh filename="file:///home/jelly/ros2_ws/install/mycobot_280_description/share/mycobot_280_description/meshes/mycobot_280/link5.stl"/>
      </geometry>
    </visual>
    <collision>
      <origin rpy="0 0 0" xyz="0 0 -0.038"/>
      <geometry>
        <mesh filename="file:///home/jelly/ros2_ws/install/mycobot_280_description/share/mycobot_280_description/meshes/mycobot_280/link5.stl"/>
      </geometry>
    </collision>
  </link>
  <link name="link6">
    <visual>
      <origin rpy="0 0 0" xyz="0 0 -0.012"/>
      <geometry>
        <mesh filename="file:///home/jelly/ros2_ws/install/mycobot_280_description/share/mycobot_280_description/meshes/mycobot_280/link6.stl"/>
      </geometry>
    </visual>
    <collision>
      <origin rpy="0 0 0" xyz="0 0 -0.012"/>
      <geometry>
        <mesh filename="file:///home/jelly/ros2_ws/install/mycobot_280_description/share/mycobot_280_description/meshes/mycobot_280/link6.stl"/>
      </geometry>
    </collision>
  </link>
  <!-- Insert new links here -->
  <link name="holder">
    <inertial>
      <origin rpy="0 0 0" xyz="9.542063908505497e-10 4.713475046347886e-13 0.051986133375594434"/>
      <mass value="2.1138978819045212e-10"/>
      <inertia ixx="0.0" ixy="0.0" ixz="0.0" iyy="0.0" iyz="0.0" izz="0.0"/>
    </inertial>
    <visual>
      <origin rpy="0 0 0" xyz="0 0 0"/>
      <geometry>
        <mesh filename="file:///home/jelly/ros2_ws/install/mycobot_description/share/mycobot_description/meshes/mycobot_280/holder.stl"/>
      </geometry>
      <material name="silver"/>
    </visual>
    <collision>
      <origin rpy="0 0 0" xyz="0 0 0"/>
      <geometry>
        <mesh filename="file:///home/jelly/ros2_ws/install/mycobot_description/share/mycobot_description/meshes/mycobot_280/holder.stl"/>
      </geometry>
    </collision>
  </link>
  <link name="spectrometer">
    <inertial>
      <origin rpy="0 0 0" xyz="9.614911284733845e-13 -7.7769165452601e-15 -0.07613934716557663"/>
      <mass value="1.4364425990347802e-11"/>
      <inertia ixx="0.0" ixy="-0.0" ixz="-0.0" iyy="0.0" iyz="0.0" izz="0.0"/>
    </inertial>
    <visual>
      <origin rpy="0 0 0" xyz="-0.0 -0.0 -0.052052"/>
      <geometry>
        <mesh filename="file:///home/jelly/ros2_ws/install/mycobot_description/share/mycobot_description/meshes/mycobot_280/spectrometer.stl"/>
      </geometry>
      <material name="silver"/>
    </visual>
    <collision>
      <origin rpy="0 0 0" xyz="-0.0 -0.0 -0.052052"/>
      <geometry>
        <mesh filename="file:///home/jelly/ros2_ws/install/mycobot_description/share/mycobot_description/meshes/mycobot_280/spectrometer.stl"/>
      </geometry>
    </collision>
  </link>
  <!-- base_joint fixes base_link to the environment -->
  <joint name="base_joint" type="fixed">
    <origin rpy="0 0 0" xyz="0 0 0"/>
    <parent link="world"/>
    <child link="base_link"/>
  </joint>
  <!-- joints - main serial chain -->
  <joint name="joint1" type="revolute">
    <parent link="base_link"/>
    <child link="link1"/>
    <origin rpy="0 0 0" xyz="0 0 0.13156"/>
    <axis xyz="0 0 1"/>
    <limit effort="1000.0" lower="-3.139847324337799" upper="3.139847324337799" velocity="0.0"/>
    <dynamics damping="0" friction="0"/>
  </joint>
  <joint name="joint2" type="revolute">
    <parent link="link1"/>
    <child link="link2"/>
    <origin rpy="0 1.5708 -1.5708" xyz="0 0 0"/>
    <axis xyz="0 0 1"/>
    <limit effort="1000.0" lower="-3.139847324337799" upper="3.139847324337799" velocity="0.0"/>
    <dynamics damping="0" friction="0"/>
  </joint>
  <joint name="joint3" type="revolute">
    <parent link="link2"/>
    <child link="link3"/>
    <origin rpy="0 0 0" xyz="-0.1104 0 0"/>
    <axis xyz="0 0 1"/>
    <limit effort="1000.0" lower="-3.139847324337799" upper="3.139847324337799" velocity="0.0"/>
    <dynamics damping="0" friction="0"/>
  </joint>
  <joint name="joint4" type="revolute">
    <parent link="link3"/>
    <child link="link4"/>
    <origin rpy="0 0 -1.5708" xyz="-0.096 0 0.06462"/>
    <axis xyz="0 0 1"/>
    <limit effort="1000.0" lower="-3.139847324337799" upper="3.139847324337799" velocity="0.0"/>
    <dynamics damping="0" friction="0"/>
  </joint>
  <joint name="joint5" type="revolute">
    <parent link="link4"/>
    <child link="link5"/>
    <origin rpy="1.5708 -1.5708 0" xyz="0 -0.07318 0"/>
    <axis xyz="0 0 1"/>
    <limit effort="1000.0" lower="-3.139847324337799" upper="3.139847324337799" velocity="0.0"/>
    <dynamics damping="0" friction="0"/>
  </joint>
  <joint name="joint6" type="revolute">
    <parent link="link5"/>
    <child link="link6"/>
    <origin rpy="-1.5708 0 0" xyz="0 0.0456 0"/>
    <axis xyz="0 0 1"/>
    <limit effort="1000.0" lower="-3.139847324337799" upper="3.139847324337799" velocity="0.0"/>
    <dynamics damping="0" friction="0"/>
  </joint>
  <!-- Add new joints here -->
  <joint name="robot_to_holder" type="fixed">
    <origin rpy="0 0 0" xyz="1.3e-05 0.0 1e-05"/>
    <parent link="link6"/>
    <child link="holder"/>
  </joint>
  <joint name="holder_to_spectrometer" type="fixed">
    <origin rpy="0 0 0" xyz="0.0 0.0 0.0"/>
    <parent link="holder"/>
    <child link="spectrometer"/>
  </joint>
</robot>
